[16/Feb/2016 11:04:57 -0800] kerberos_    ERROR    generate_request_header(): authGSSClientStep() failed:
Traceback (most recent call last):
  File "/opt/cloudera/parcels/CDH-5.5.1-1.cdh5.5.1.p0.11/lib/hue/build/env/lib/python2.7/site-packages/requests_kerberos-0.6.1-py2.7.egg/requests_kerberos/kerberos_.py", line 114, in generate_request_header
    _negotiate_value(response))
GSSError: (('Unspecified GSS failure.  Minor code may provide more information', 851968), ('No Kerberos credentials available', -1765328243))
[16/Feb/2016 11:04:57 -0800] kerberos_    ERROR    authenticate_server(): authGSSClientStep() failed:
Traceback (most recent call last):
  File "/opt/cloudera/parcels/CDH-5.5.1-1.cdh5.5.1.p0.11/lib/hue/build/env/lib/python2.7/site-packages/requests_kerberos-0.6.1-py2.7.egg/requests_kerberos/kerberos_.py", line 229, in authenticate_server
    _negotiate_value(response))
GSSError: (('Unspecified GSS failure.  Minor code may provide more information', 851968), ('No Kerberos credentials available', -1765328243))
[16/Feb/2016 11:04:57 -0800] kerberos_    ERROR    handle_mutual_auth(): Mutual authentication failed
[16/Feb/2016 11:04:57 -0800] models       ERROR    Failed to create home directory for user hue: Unable to authenticate <Response [401]>
Traceback (most recent call last):
  File "/opt/cloudera/parcels/CDH-5.5.1-1.cdh5.5.1.p0.11/lib/hue/apps/useradmin/src/useradmin/models.py", line 326, in install_sample_user
    if not fs.do_as_user(SAMPLE_USER_INSTALL, fs.get_home_dir):
  File "/opt/cloudera/parcels/CDH-5.5.1-1.cdh5.5.1.p0.11/lib/hue/desktop/libs/hadoop/src/hadoop/fs/webhdfs.py", line 753, in do_as_user
    return fn(*args, **kwargs)
  File "/opt/cloudera/parcels/CDH-5.5.1-1.cdh5.5.1.p0.11/lib/hue/desktop/libs/hadoop/src/hadoop/fs/webhdfs.py", line 442, in get_home_dir
    res = self._root.get(params=params)
  File "/opt/cloudera/parcels/CDH-5.5.1-1.cdh5.5.1.p0.11/lib/hue/desktop/core/src/desktop/lib/rest/resource.py", line 97, in get
    return self.invoke("GET", relpath, params, headers=headers, allow_redirects=True)
  File "/opt/cloudera/parcels/CDH-5.5.1-1.cdh5.5.1.p0.11/lib/hue/desktop/core/src/desktop/lib/rest/resource.py", line 78, in invoke
    urlencode=self._urlencode)
  File "/opt/cloudera/parcels/CDH-5.5.1-1.cdh5.5.1.p0.11/lib/hue/desktop/core/src/desktop/lib/rest/http_client.py", line 161, in execute
    raise self._exc_class(ex)
WebHdfsException: Unable to authenticate <Response [401]>
[16/Feb/2016 11:04:57 -0800] kerberos_    ERROR    generate_request_header(): authGSSClientStep() failed:
Traceback (most recent call last):
  File "/opt/cloudera/parcels/CDH-5.5.1-1.cdh5.5.1.p0.11/lib/hue/build/env/lib/python2.7/site-packages/requests_kerberos-0.6.1-py2.7.egg/requests_kerberos/kerberos_.py", line 114, in generate_request_header
    _negotiate_value(response))
GSSError: (('Unspecified GSS failure.  Minor code may provide more information', 851968), ('No Kerberos credentials available', -1765328243))
[16/Feb/2016 11:04:57 -0800] kerberos_    ERROR    authenticate_server(): authGSSClientStep() failed:
Traceback (most recent call last):
  File "/opt/cloudera/parcels/CDH-5.5.1-1.cdh5.5.1.p0.11/lib/hue/build/env/lib/python2.7/site-packages/requests_kerberos-0.6.1-py2.7.egg/requests_kerberos/kerberos_.py", line 229, in authenticate_server
    _negotiate_value(response))
GSSError: (('Unspecified GSS failure.  Minor code may provide more information', 851968), ('No Kerberos credentials available', -1765328243))
[16/Feb/2016 11:04:57 -0800] kerberos_    ERROR    handle_mutual_auth(): Mutual authentication failed
[16/Feb/2016 11:04:57 -0800] models       ERROR    Failed to create home directory for user hue: Unable to authenticate <Response [401]>
Traceback (most recent call last):
  File "/opt/cloudera/parcels/CDH-5.5.1-1.cdh5.5.1.p0.11/lib/hue/apps/useradmin/src/useradmin/models.py", line 326, in install_sample_user
    if not fs.do_as_user(SAMPLE_USER_INSTALL, fs.get_home_dir):
  File "/opt/cloudera/parcels/CDH-5.5.1-1.cdh5.5.1.p0.11/lib/hue/desktop/libs/hadoop/src/hadoop/fs/webhdfs.py", line 753, in do_as_user
    return fn(*args, **kwargs)
  File "/opt/cloudera/parcels/CDH-5.5.1-1.cdh5.5.1.p0.11/lib/hue/desktop/libs/hadoop/src/hadoop/fs/webhdfs.py", line 442, in get_home_dir
    res = self._root.get(params=params)
  File "/opt/cloudera/parcels/CDH-5.5.1-1.cdh5.5.1.p0.11/lib/hue/desktop/core/src/desktop/lib/rest/resource.py", line 97, in get
    return self.invoke("GET", relpath, params, headers=headers, allow_redirects=True)
  File "/opt/cloudera/parcels/CDH-5.5.1-1.cdh5.5.1.p0.11/lib/hue/desktop/core/src/desktop/lib/rest/resource.py", line 78, in invoke
    urlencode=self._urlencode)
  File "/opt/cloudera/parcels/CDH-5.5.1-1.cdh5.5.1.p0.11/lib/hue/desktop/core/src/desktop/lib/rest/http_client.py", line 161, in execute
    raise self._exc_class(ex)
WebHdfsException: Unable to authenticate <Response [401]>
[16/Feb/2016 11:04:57 -0800] kerberos_    ERROR    generate_request_header(): authGSSClientStep() failed:
Traceback (most recent call last):
  File "/opt/cloudera/parcels/CDH-5.5.1-1.cdh5.5.1.p0.11/lib/hue/build/env/lib/python2.7/site-packages/requests_kerberos-0.6.1-py2.7.egg/requests_kerberos/kerberos_.py", line 114, in generate_request_header
    _negotiate_value(response))
GSSError: (('Unspecified GSS failure.  Minor code may provide more information', 851968), ('No Kerberos credentials available', -1765328243))
[16/Feb/2016 11:04:57 -0800] kerberos_    ERROR    authenticate_server(): authGSSClientStep() failed:
Traceback (most recent call last):
  File "/opt/cloudera/parcels/CDH-5.5.1-1.cdh5.5.1.p0.11/lib/hue/build/env/lib/python2.7/site-packages/requests_kerberos-0.6.1-py2.7.egg/requests_kerberos/kerberos_.py", line 229, in authenticate_server
    _negotiate_value(response))
GSSError: (('Unspecified GSS failure.  Minor code may provide more information', 851968), ('No Kerberos credentials available', -1765328243))
[16/Feb/2016 11:04:58 -0800] kerberos_    ERROR    handle_mutual_auth(): Mutual authentication failed
[16/Feb/2016 11:04:58 -0800] models       ERROR    Failed to create home directory for user hue: Unable to authenticate <Response [401]>
Traceback (most recent call last):
  File "/opt/cloudera/parcels/CDH-5.5.1-1.cdh5.5.1.p0.11/lib/hue/apps/useradmin/src/useradmin/models.py", line 326, in install_sample_user
    if not fs.do_as_user(SAMPLE_USER_INSTALL, fs.get_home_dir):
  File "/opt/cloudera/parcels/CDH-5.5.1-1.cdh5.5.1.p0.11/lib/hue/desktop/libs/hadoop/src/hadoop/fs/webhdfs.py", line 753, in do_as_user
    return fn(*args, **kwargs)
  File "/opt/cloudera/parcels/CDH-5.5.1-1.cdh5.5.1.p0.11/lib/hue/desktop/libs/hadoop/src/hadoop/fs/webhdfs.py", line 442, in get_home_dir
    res = self._root.get(params=params)
  File "/opt/cloudera/parcels/CDH-5.5.1-1.cdh5.5.1.p0.11/lib/hue/desktop/core/src/desktop/lib/rest/resource.py", line 97, in get
    return self.invoke("GET", relpath, params, headers=headers, allow_redirects=True)
  File "/opt/cloudera/parcels/CDH-5.5.1-1.cdh5.5.1.p0.11/lib/hue/desktop/core/src/desktop/lib/rest/resource.py", line 78, in invoke
    urlencode=self._urlencode)
  File "/opt/cloudera/parcels/CDH-5.5.1-1.cdh5.5.1.p0.11/lib/hue/desktop/core/src/desktop/lib/rest/http_client.py", line 161, in execute
    raise self._exc_class(ex)
WebHdfsException: Unable to authenticate <Response [401]>
[16/Feb/2016 11:04:58 -0800] kerberos_    ERROR    generate_request_header(): authGSSClientStep() failed:
Traceback (most recent call last):
  File "/opt/cloudera/parcels/CDH-5.5.1-1.cdh5.5.1.p0.11/lib/hue/build/env/lib/python2.7/site-packages/requests_kerberos-0.6.1-py2.7.egg/requests_kerberos/kerberos_.py", line 114, in generate_request_header
    _negotiate_value(response))
GSSError: (('Unspecified GSS failure.  Minor code may provide more information', 851968), ('No Kerberos credentials available', -1765328243))
[16/Feb/2016 11:04:58 -0800] kerberos_    ERROR    authenticate_server(): authGSSClientStep() failed:
Traceback (most recent call last):
  File "/opt/cloudera/parcels/CDH-5.5.1-1.cdh5.5.1.p0.11/lib/hue/build/env/lib/python2.7/site-packages/requests_kerberos-0.6.1-py2.7.egg/requests_kerberos/kerberos_.py", line 229, in authenticate_server
    _negotiate_value(response))
GSSError: (('Unspecified GSS failure.  Minor code may provide more information', 851968), ('No Kerberos credentials available', -1765328243))
[16/Feb/2016 11:04:58 -0800] kerberos_    ERROR    handle_mutual_auth(): Mutual authentication failed
[16/Feb/2016 11:04:58 -0800] models       ERROR    Failed to create home directory for user hue: Unable to authenticate <Response [401]>
Traceback (most recent call last):
  File "/opt/cloudera/parcels/CDH-5.5.1-1.cdh5.5.1.p0.11/lib/hue/apps/useradmin/src/useradmin/models.py", line 326, in install_sample_user
    if not fs.do_as_user(SAMPLE_USER_INSTALL, fs.get_home_dir):
  File "/opt/cloudera/parcels/CDH-5.5.1-1.cdh5.5.1.p0.11/lib/hue/desktop/libs/hadoop/src/hadoop/fs/webhdfs.py", line 753, in do_as_user
    return fn(*args, **kwargs)
  File "/opt/cloudera/parcels/CDH-5.5.1-1.cdh5.5.1.p0.11/lib/hue/desktop/libs/hadoop/src/hadoop/fs/webhdfs.py", line 442, in get_home_dir
    res = self._root.get(params=params)
  File "/opt/cloudera/parcels/CDH-5.5.1-1.cdh5.5.1.p0.11/lib/hue/desktop/core/src/desktop/lib/rest/resource.py", line 97, in get
    return self.invoke("GET", relpath, params, headers=headers, allow_redirects=True)
  File "/opt/cloudera/parcels/CDH-5.5.1-1.cdh5.5.1.p0.11/lib/hue/desktop/core/src/desktop/lib/rest/resource.py", line 78, in invoke
    urlencode=self._urlencode)
  File "/opt/cloudera/parcels/CDH-5.5.1-1.cdh5.5.1.p0.11/lib/hue/desktop/core/src/desktop/lib/rest/http_client.py", line 161, in execute
    raise self._exc_class(ex)
WebHdfsException: Unable to authenticate <Response [401]>
[16/Feb/2016 11:04:58 -0800] kerberos_    ERROR    generate_request_header(): authGSSClientStep() failed:
Traceback (most recent call last):
  File "/opt/cloudera/parcels/CDH-5.5.1-1.cdh5.5.1.p0.11/lib/hue/build/env/lib/python2.7/site-packages/requests_kerberos-0.6.1-py2.7.egg/requests_kerberos/kerberos_.py", line 114, in generate_request_header
    _negotiate_value(response))
GSSError: (('Unspecified GSS failure.  Minor code may provide more information', 851968), ('No Kerberos credentials available', -1765328243))
[16/Feb/2016 11:04:58 -0800] kerberos_    ERROR    authenticate_server(): authGSSClientStep() failed:
Traceback (most recent call last):
  File "/opt/cloudera/parcels/CDH-5.5.1-1.cdh5.5.1.p0.11/lib/hue/build/env/lib/python2.7/site-packages/requests_kerberos-0.6.1-py2.7.egg/requests_kerberos/kerberos_.py", line 229, in authenticate_server
    _negotiate_value(response))
GSSError: (('Unspecified GSS failure.  Minor code may provide more information', 851968), ('No Kerberos credentials available', -1765328243))
[16/Feb/2016 11:04:58 -0800] kerberos_    ERROR    handle_mutual_auth(): Mutual authentication failed
[16/Feb/2016 11:04:58 -0800] models       ERROR    Failed to create home directory for user hue: Unable to authenticate <Response [401]>
Traceback (most recent call last):
  File "/opt/cloudera/parcels/CDH-5.5.1-1.cdh5.5.1.p0.11/lib/hue/apps/useradmin/src/useradmin/models.py", line 326, in install_sample_user
    if not fs.do_as_user(SAMPLE_USER_INSTALL, fs.get_home_dir):
  File "/opt/cloudera/parcels/CDH-5.5.1-1.cdh5.5.1.p0.11/lib/hue/desktop/libs/hadoop/src/hadoop/fs/webhdfs.py", line 753, in do_as_user
    return fn(*args, **kwargs)
  File "/opt/cloudera/parcels/CDH-5.5.1-1.cdh5.5.1.p0.11/lib/hue/desktop/libs/hadoop/src/hadoop/fs/webhdfs.py", line 442, in get_home_dir
    res = self._root.get(params=params)
  File "/opt/cloudera/parcels/CDH-5.5.1-1.cdh5.5.1.p0.11/lib/hue/desktop/core/src/desktop/lib/rest/resource.py", line 97, in get
    return self.invoke("GET", relpath, params, headers=headers, allow_redirects=True)
  File "/opt/cloudera/parcels/CDH-5.5.1-1.cdh5.5.1.p0.11/lib/hue/desktop/core/src/desktop/lib/rest/resource.py", line 78, in invoke
    urlencode=self._urlencode)
  File "/opt/cloudera/parcels/CDH-5.5.1-1.cdh5.5.1.p0.11/lib/hue/desktop/core/src/desktop/lib/rest/http_client.py", line 161, in execute
    raise self._exc_class(ex)
WebHdfsException: Unable to authenticate <Response [401]>
[16/Feb/2016 11:04:58 -0800] kerberos_    ERROR    generate_request_header(): authGSSClientStep() failed:
Traceback (most recent call last):
  File "/opt/cloudera/parcels/CDH-5.5.1-1.cdh5.5.1.p0.11/lib/hue/build/env/lib/python2.7/site-packages/requests_kerberos-0.6.1-py2.7.egg/requests_kerberos/kerberos_.py", line 114, in generate_request_header
    _negotiate_value(response))
GSSError: (('Unspecified GSS failure.  Minor code may provide more information', 851968), ('No Kerberos credentials available', -1765328243))
[16/Feb/2016 11:04:58 -0800] kerberos_    ERROR    authenticate_server(): authGSSClientStep() failed:
Traceback (most recent call last):
  File "/opt/cloudera/parcels/CDH-5.5.1-1.cdh5.5.1.p0.11/lib/hue/build/env/lib/python2.7/site-packages/requests_kerberos-0.6.1-py2.7.egg/requests_kerberos/kerberos_.py", line 229, in authenticate_server
    _negotiate_value(response))
GSSError: (('Unspecified GSS failure.  Minor code may provide more information', 851968), ('No Kerberos credentials available', -1765328243))
[16/Feb/2016 11:04:58 -0800] kerberos_    ERROR    handle_mutual_auth(): Mutual authentication failed
[16/Feb/2016 11:04:58 -0800] models       ERROR    Failed to create home directory for user hue: Unable to authenticate <Response [401]>
Traceback (most recent call last):
  File "/opt/cloudera/parcels/CDH-5.5.1-1.cdh5.5.1.p0.11/lib/hue/apps/useradmin/src/useradmin/models.py", line 326, in install_sample_user
    if not fs.do_as_user(SAMPLE_USER_INSTALL, fs.get_home_dir):
  File "/opt/cloudera/parcels/CDH-5.5.1-1.cdh5.5.1.p0.11/lib/hue/desktop/libs/hadoop/src/hadoop/fs/webhdfs.py", line 753, in do_as_user
    return fn(*args, **kwargs)
  File "/opt/cloudera/parcels/CDH-5.5.1-1.cdh5.5.1.p0.11/lib/hue/desktop/libs/hadoop/src/hadoop/fs/webhdfs.py", line 442, in get_home_dir
    res = self._root.get(params=params)
  File "/opt/cloudera/parcels/CDH-5.5.1-1.cdh5.5.1.p0.11/lib/hue/desktop/core/src/desktop/lib/rest/resource.py", line 97, in get
    return self.invoke("GET", relpath, params, headers=headers, allow_redirects=True)
  File "/opt/cloudera/parcels/CDH-5.5.1-1.cdh5.5.1.p0.11/lib/hue/desktop/core/src/desktop/lib/rest/resource.py", line 78, in invoke
    urlencode=self._urlencode)
  File "/opt/cloudera/parcels/CDH-5.5.1-1.cdh5.5.1.p0.11/lib/hue/desktop/core/src/desktop/lib/rest/http_client.py", line 161, in execute
    raise self._exc_class(ex)
WebHdfsException: Unable to authenticate <Response [401]>
[16/Feb/2016 11:04:58 -0800] kerberos_    ERROR    generate_request_header(): authGSSClientStep() failed:
Traceback (most recent call last):
  File "/opt/cloudera/parcels/CDH-5.5.1-1.cdh5.5.1.p0.11/lib/hue/build/env/lib/python2.7/site-packages/requests_kerberos-0.6.1-py2.7.egg/requests_kerberos/kerberos_.py", line 114, in generate_request_header
    _negotiate_value(response))
GSSError: (('Unspecified GSS failure.  Minor code may provide more information', 851968), ('No Kerberos credentials available', -1765328243))
[16/Feb/2016 11:04:58 -0800] kerberos_    ERROR    authenticate_server(): authGSSClientStep() failed:
Traceback (most recent call last):
  File "/opt/cloudera/parcels/CDH-5.5.1-1.cdh5.5.1.p0.11/lib/hue/build/env/lib/python2.7/site-packages/requests_kerberos-0.6.1-py2.7.egg/requests_kerberos/kerberos_.py", line 229, in authenticate_server
    _negotiate_value(response))
GSSError: (('Unspecified GSS failure.  Minor code may provide more information', 851968), ('No Kerberos credentials available', -1765328243))
[16/Feb/2016 11:04:58 -0800] kerberos_    ERROR    handle_mutual_auth(): Mutual authentication failed
[16/Feb/2016 11:04:58 -0800] models       ERROR    Failed to create home directory for user hue: Unable to authenticate <Response [401]>
Traceback (most recent call last):
  File "/opt/cloudera/parcels/CDH-5.5.1-1.cdh5.5.1.p0.11/lib/hue/apps/useradmin/src/useradmin/models.py", line 326, in install_sample_user
    if not fs.do_as_user(SAMPLE_USER_INSTALL, fs.get_home_dir):
  File "/opt/cloudera/parcels/CDH-5.5.1-1.cdh5.5.1.p0.11/lib/hue/desktop/libs/hadoop/src/hadoop/fs/webhdfs.py", line 753, in do_as_user
    return fn(*args, **kwargs)
  File "/opt/cloudera/parcels/CDH-5.5.1-1.cdh5.5.1.p0.11/lib/hue/desktop/libs/hadoop/src/hadoop/fs/webhdfs.py", line 442, in get_home_dir
    res = self._root.get(params=params)
  File "/opt/cloudera/parcels/CDH-5.5.1-1.cdh5.5.1.p0.11/lib/hue/desktop/core/src/desktop/lib/rest/resource.py", line 97, in get
    return self.invoke("GET", relpath, params, headers=headers, allow_redirects=True)
  File "/opt/cloudera/parcels/CDH-5.5.1-1.cdh5.5.1.p0.11/lib/hue/desktop/core/src/desktop/lib/rest/resource.py", line 78, in invoke
    urlencode=self._urlencode)
  File "/opt/cloudera/parcels/CDH-5.5.1-1.cdh5.5.1.p0.11/lib/hue/desktop/core/src/desktop/lib/rest/http_client.py", line 161, in execute
    raise self._exc_class(ex)
WebHdfsException: Unable to authenticate <Response [401]>
[16/Feb/2016 11:04:58 -0800] kerberos_    ERROR    generate_request_header(): authGSSClientStep() failed:
Traceback (most recent call last):
  File "/opt/cloudera/parcels/CDH-5.5.1-1.cdh5.5.1.p0.11/lib/hue/build/env/lib/python2.7/site-packages/requests_kerberos-0.6.1-py2.7.egg/requests_kerberos/kerberos_.py", line 114, in generate_request_header
    _negotiate_value(response))
GSSError: (('Unspecified GSS failure.  Minor code may provide more information', 851968), ('No Kerberos credentials available', -1765328243))
[16/Feb/2016 11:04:58 -0800] kerberos_    ERROR    authenticate_server(): authGSSClientStep() failed:
Traceback (most recent call last):
  File "/opt/cloudera/parcels/CDH-5.5.1-1.cdh5.5.1.p0.11/lib/hue/build/env/lib/python2.7/site-packages/requests_kerberos-0.6.1-py2.7.egg/requests_kerberos/kerberos_.py", line 229, in authenticate_server
    _negotiate_value(response))
GSSError: (('Unspecified GSS failure.  Minor code may provide more information', 851968), ('No Kerberos credentials available', -1765328243))
[16/Feb/2016 11:04:58 -0800] kerberos_    ERROR    handle_mutual_auth(): Mutual authentication failed
[16/Feb/2016 11:04:58 -0800] models       ERROR    Failed to create home directory for user hue: Unable to authenticate <Response [401]>
Traceback (most recent call last):
  File "/opt/cloudera/parcels/CDH-5.5.1-1.cdh5.5.1.p0.11/lib/hue/apps/useradmin/src/useradmin/models.py", line 326, in install_sample_user
    if not fs.do_as_user(SAMPLE_USER_INSTALL, fs.get_home_dir):
  File "/opt/cloudera/parcels/CDH-5.5.1-1.cdh5.5.1.p0.11/lib/hue/desktop/libs/hadoop/src/hadoop/fs/webhdfs.py", line 753, in do_as_user
    return fn(*args, **kwargs)
  File "/opt/cloudera/parcels/CDH-5.5.1-1.cdh5.5.1.p0.11/lib/hue/desktop/libs/hadoop/src/hadoop/fs/webhdfs.py", line 442, in get_home_dir
    res = self._root.get(params=params)
  File "/opt/cloudera/parcels/CDH-5.5.1-1.cdh5.5.1.p0.11/lib/hue/desktop/core/src/desktop/lib/rest/resource.py", line 97, in get
    return self.invoke("GET", relpath, params, headers=headers, allow_redirects=True)
  File "/opt/cloudera/parcels/CDH-5.5.1-1.cdh5.5.1.p0.11/lib/hue/desktop/core/src/desktop/lib/rest/resource.py", line 78, in invoke
    urlencode=self._urlencode)
  File "/opt/cloudera/parcels/CDH-5.5.1-1.cdh5.5.1.p0.11/lib/hue/desktop/core/src/desktop/lib/rest/http_client.py", line 161, in execute
    raise self._exc_class(ex)
WebHdfsException: Unable to authenticate <Response [401]>
[16/Feb/2016 11:04:58 -0800] kerberos_    ERROR    generate_request_header(): authGSSClientStep() failed:
Traceback (most recent call last):
  File "/opt/cloudera/parcels/CDH-5.5.1-1.cdh5.5.1.p0.11/lib/hue/build/env/lib/python2.7/site-packages/requests_kerberos-0.6.1-py2.7.egg/requests_kerberos/kerberos_.py", line 114, in generate_request_header
    _negotiate_value(response))
GSSError: (('Unspecified GSS failure.  Minor code may provide more information', 851968), ('No Kerberos credentials available', -1765328243))
[16/Feb/2016 11:04:58 -0800] kerberos_    ERROR    authenticate_server(): authGSSClientStep() failed:
Traceback (most recent call last):
  File "/opt/cloudera/parcels/CDH-5.5.1-1.cdh5.5.1.p0.11/lib/hue/build/env/lib/python2.7/site-packages/requests_kerberos-0.6.1-py2.7.egg/requests_kerberos/kerberos_.py", line 229, in authenticate_server
    _negotiate_value(response))
GSSError: (('Unspecified GSS failure.  Minor code may provide more information', 851968), ('No Kerberos credentials available', -1765328243))
[16/Feb/2016 11:04:58 -0800] kerberos_    ERROR    handle_mutual_auth(): Mutual authentication failed
[16/Feb/2016 11:04:58 -0800] models       ERROR    Failed to create home directory for user hue: Unable to authenticate <Response [401]>
Traceback (most recent call last):
  File "/opt/cloudera/parcels/CDH-5.5.1-1.cdh5.5.1.p0.11/lib/hue/apps/useradmin/src/useradmin/models.py", line 326, in install_sample_user
    if not fs.do_as_user(SAMPLE_USER_INSTALL, fs.get_home_dir):
  File "/opt/cloudera/parcels/CDH-5.5.1-1.cdh5.5.1.p0.11/lib/hue/desktop/libs/hadoop/src/hadoop/fs/webhdfs.py", line 753, in do_as_user
    return fn(*args, **kwargs)
  File "/opt/cloudera/parcels/CDH-5.5.1-1.cdh5.5.1.p0.11/lib/hue/desktop/libs/hadoop/src/hadoop/fs/webhdfs.py", line 442, in get_home_dir
    res = self._root.get(params=params)
  File "/opt/cloudera/parcels/CDH-5.5.1-1.cdh5.5.1.p0.11/lib/hue/desktop/core/src/desktop/lib/rest/resource.py", line 97, in get
    return self.invoke("GET", relpath, params, headers=headers, allow_redirects=True)
  File "/opt/cloudera/parcels/CDH-5.5.1-1.cdh5.5.1.p0.11/lib/hue/desktop/core/src/desktop/lib/rest/resource.py", line 78, in invoke
    urlencode=self._urlencode)
  File "/opt/cloudera/parcels/CDH-5.5.1-1.cdh5.5.1.p0.11/lib/hue/desktop/core/src/desktop/lib/rest/http_client.py", line 161, in execute
    raise self._exc_class(ex)
WebHdfsException: Unable to authenticate <Response [401]>
[16/Feb/2016 11:04:58 -0800] kerberos_    ERROR    generate_request_header(): authGSSClientStep() failed:
Traceback (most recent call last):
  File "/opt/cloudera/parcels/CDH-5.5.1-1.cdh5.5.1.p0.11/lib/hue/build/env/lib/python2.7/site-packages/requests_kerberos-0.6.1-py2.7.egg/requests_kerberos/kerberos_.py", line 114, in generate_request_header
    _negotiate_value(response))
GSSError: (('Unspecified GSS failure.  Minor code may provide more information', 851968), ('No Kerberos credentials available', -1765328243))
[16/Feb/2016 11:04:58 -0800] kerberos_    ERROR    authenticate_server(): authGSSClientStep() failed:
Traceback (most recent call last):
  File "/opt/cloudera/parcels/CDH-5.5.1-1.cdh5.5.1.p0.11/lib/hue/build/env/lib/python2.7/site-packages/requests_kerberos-0.6.1-py2.7.egg/requests_kerberos/kerberos_.py", line 229, in authenticate_server
    _negotiate_value(response))
GSSError: (('Unspecified GSS failure.  Minor code may provide more information', 851968), ('No Kerberos credentials available', -1765328243))
[16/Feb/2016 11:04:58 -0800] kerberos_    ERROR    handle_mutual_auth(): Mutual authentication failed
[16/Feb/2016 11:04:58 -0800] models       ERROR    Failed to create home directory for user hue: Unable to authenticate <Response [401]>
Traceback (most recent call last):
  File "/opt/cloudera/parcels/CDH-5.5.1-1.cdh5.5.1.p0.11/lib/hue/apps/useradmin/src/useradmin/models.py", line 326, in install_sample_user
    if not fs.do_as_user(SAMPLE_USER_INSTALL, fs.get_home_dir):
  File "/opt/cloudera/parcels/CDH-5.5.1-1.cdh5.5.1.p0.11/lib/hue/desktop/libs/hadoop/src/hadoop/fs/webhdfs.py", line 753, in do_as_user
    return fn(*args, **kwargs)
  File "/opt/cloudera/parcels/CDH-5.5.1-1.cdh5.5.1.p0.11/lib/hue/desktop/libs/hadoop/src/hadoop/fs/webhdfs.py", line 442, in get_home_dir
    res = self._root.get(params=params)
  File "/opt/cloudera/parcels/CDH-5.5.1-1.cdh5.5.1.p0.11/lib/hue/desktop/core/src/desktop/lib/rest/resource.py", line 97, in get
    return self.invoke("GET", relpath, params, headers=headers, allow_redirects=True)
  File "/opt/cloudera/parcels/CDH-5.5.1-1.cdh5.5.1.p0.11/lib/hue/desktop/core/src/desktop/lib/rest/resource.py", line 78, in invoke
    urlencode=self._urlencode)
  File "/opt/cloudera/parcels/CDH-5.5.1-1.cdh5.5.1.p0.11/lib/hue/desktop/core/src/desktop/lib/rest/http_client.py", line 161, in execute
    raise self._exc_class(ex)
WebHdfsException: Unable to authenticate <Response [401]>
[16/Feb/2016 11:04:58 -0800] kerberos_    ERROR    generate_request_header(): authGSSClientStep() failed:
Traceback (most recent call last):
  File "/opt/cloudera/parcels/CDH-5.5.1-1.cdh5.5.1.p0.11/lib/hue/build/env/lib/python2.7/site-packages/requests_kerberos-0.6.1-py2.7.egg/requests_kerberos/kerberos_.py", line 114, in generate_request_header
    _negotiate_value(response))
GSSError: (('Unspecified GSS failure.  Minor code may provide more information', 851968), ('No Kerberos credentials available', -1765328243))
[16/Feb/2016 11:04:58 -0800] kerberos_    ERROR    authenticate_server(): authGSSClientStep() failed:
Traceback (most recent call last):
  File "/opt/cloudera/parcels/CDH-5.5.1-1.cdh5.5.1.p0.11/lib/hue/build/env/lib/python2.7/site-packages/requests_kerberos-0.6.1-py2.7.egg/requests_kerberos/kerberos_.py", line 229, in authenticate_server
    _negotiate_value(response))
GSSError: (('Unspecified GSS failure.  Minor code may provide more information', 851968), ('No Kerberos credentials available', -1765328243))
[16/Feb/2016 11:04:58 -0800] kerberos_    ERROR    handle_mutual_auth(): Mutual authentication failed
[16/Feb/2016 11:04:58 -0800] models       ERROR    Failed to create home directory for user hue: Unable to authenticate <Response [401]>
Traceback (most recent call last):
  File "/opt/cloudera/parcels/CDH-5.5.1-1.cdh5.5.1.p0.11/lib/hue/apps/useradmin/src/useradmin/models.py", line 326, in install_sample_user
    if not fs.do_as_user(SAMPLE_USER_INSTALL, fs.get_home_dir):
  File "/opt/cloudera/parcels/CDH-5.5.1-1.cdh5.5.1.p0.11/lib/hue/desktop/libs/hadoop/src/hadoop/fs/webhdfs.py", line 753, in do_as_user
    return fn(*args, **kwargs)
  File "/opt/cloudera/parcels/CDH-5.5.1-1.cdh5.5.1.p0.11/lib/hue/desktop/libs/hadoop/src/hadoop/fs/webhdfs.py", line 442, in get_home_dir
    res = self._root.get(params=params)
  File "/opt/cloudera/parcels/CDH-5.5.1-1.cdh5.5.1.p0.11/lib/hue/desktop/core/src/desktop/lib/rest/resource.py", line 97, in get
    return self.invoke("GET", relpath, params, headers=headers, allow_redirects=True)
  File "/opt/cloudera/parcels/CDH-5.5.1-1.cdh5.5.1.p0.11/lib/hue/desktop/core/src/desktop/lib/rest/resource.py", line 78, in invoke
    urlencode=self._urlencode)
  File "/opt/cloudera/parcels/CDH-5.5.1-1.cdh5.5.1.p0.11/lib/hue/desktop/core/src/desktop/lib/rest/http_client.py", line 161, in execute
    raise self._exc_class(ex)
WebHdfsException: Unable to authenticate <Response [401]>
[16/Feb/2016 11:04:58 -0800] kerberos_    ERROR    generate_request_header(): authGSSClientStep() failed:
Traceback (most recent call last):
  File "/opt/cloudera/parcels/CDH-5.5.1-1.cdh5.5.1.p0.11/lib/hue/build/env/lib/python2.7/site-packages/requests_kerberos-0.6.1-py2.7.egg/requests_kerberos/kerberos_.py", line 114, in generate_request_header
    _negotiate_value(response))
GSSError: (('Unspecified GSS failure.  Minor code may provide more information', 851968), ('No Kerberos credentials available', -1765328243))
[16/Feb/2016 11:04:58 -0800] kerberos_    ERROR    authenticate_server(): authGSSClientStep() failed:
Traceback (most recent call last):
  File "/opt/cloudera/parcels/CDH-5.5.1-1.cdh5.5.1.p0.11/lib/hue/build/env/lib/python2.7/site-packages/requests_kerberos-0.6.1-py2.7.egg/requests_kerberos/kerberos_.py", line 229, in authenticate_server
    _negotiate_value(response))
GSSError: (('Unspecified GSS failure.  Minor code may provide more information', 851968), ('No Kerberos credentials available', -1765328243))
[16/Feb/2016 11:04:58 -0800] kerberos_    ERROR    handle_mutual_auth(): Mutual authentication failed
[16/Feb/2016 11:04:58 -0800] models       ERROR    Failed to create home directory for user hue: Unable to authenticate <Response [401]>
Traceback (most recent call last):
  File "/opt/cloudera/parcels/CDH-5.5.1-1.cdh5.5.1.p0.11/lib/hue/apps/useradmin/src/useradmin/models.py", line 326, in install_sample_user
    if not fs.do_as_user(SAMPLE_USER_INSTALL, fs.get_home_dir):
  File "/opt/cloudera/parcels/CDH-5.5.1-1.cdh5.5.1.p0.11/lib/hue/desktop/libs/hadoop/src/hadoop/fs/webhdfs.py", line 753, in do_as_user
    return fn(*args, **kwargs)
  File "/opt/cloudera/parcels/CDH-5.5.1-1.cdh5.5.1.p0.11/lib/hue/desktop/libs/hadoop/src/hadoop/fs/webhdfs.py", line 442, in get_home_dir
    res = self._root.get(params=params)
  File "/opt/cloudera/parcels/CDH-5.5.1-1.cdh5.5.1.p0.11/lib/hue/desktop/core/src/desktop/lib/rest/resource.py", line 97, in get
    return self.invoke("GET", relpath, params, headers=headers, allow_redirects=True)
  File "/opt/cloudera/parcels/CDH-5.5.1-1.cdh5.5.1.p0.11/lib/hue/desktop/core/src/desktop/lib/rest/resource.py", line 78, in invoke
    urlencode=self._urlencode)
  File "/opt/cloudera/parcels/CDH-5.5.1-1.cdh5.5.1.p0.11/lib/hue/desktop/core/src/desktop/lib/rest/http_client.py", line 161, in execute
    raise self._exc_class(ex)
WebHdfsException: Unable to authenticate <Response [401]>
[16/Feb/2016 11:04:58 -0800] kerberos_    ERROR    generate_request_header(): authGSSClientStep() failed:
Traceback (most recent call last):
  File "/opt/cloudera/parcels/CDH-5.5.1-1.cdh5.5.1.p0.11/lib/hue/build/env/lib/python2.7/site-packages/requests_kerberos-0.6.1-py2.7.egg/requests_kerberos/kerberos_.py", line 114, in generate_request_header
    _negotiate_value(response))
GSSError: (('Unspecified GSS failure.  Minor code may provide more information', 851968), ('No Kerberos credentials available', -1765328243))
[16/Feb/2016 11:04:58 -0800] kerberos_    ERROR    authenticate_server(): authGSSClientStep() failed:
Traceback (most recent call last):
  File "/opt/cloudera/parcels/CDH-5.5.1-1.cdh5.5.1.p0.11/lib/hue/build/env/lib/python2.7/site-packages/requests_kerberos-0.6.1-py2.7.egg/requests_kerberos/kerberos_.py", line 229, in authenticate_server
    _negotiate_value(response))
GSSError: (('Unspecified GSS failure.  Minor code may provide more information', 851968), ('No Kerberos credentials available', -1765328243))
[16/Feb/2016 11:04:58 -0800] kerberos_    ERROR    handle_mutual_auth(): Mutual authentication failed
[16/Feb/2016 11:04:58 -0800] models       ERROR    Failed to create home directory for user hue: Unable to authenticate <Response [401]>
Traceback (most recent call last):
  File "/opt/cloudera/parcels/CDH-5.5.1-1.cdh5.5.1.p0.11/lib/hue/apps/useradmin/src/useradmin/models.py", line 326, in install_sample_user
    if not fs.do_as_user(SAMPLE_USER_INSTALL, fs.get_home_dir):
  File "/opt/cloudera/parcels/CDH-5.5.1-1.cdh5.5.1.p0.11/lib/hue/desktop/libs/hadoop/src/hadoop/fs/webhdfs.py", line 753, in do_as_user
    return fn(*args, **kwargs)
  File "/opt/cloudera/parcels/CDH-5.5.1-1.cdh5.5.1.p0.11/lib/hue/desktop/libs/hadoop/src/hadoop/fs/webhdfs.py", line 442, in get_home_dir
    res = self._root.get(params=params)
  File "/opt/cloudera/parcels/CDH-5.5.1-1.cdh5.5.1.p0.11/lib/hue/desktop/core/src/desktop/lib/rest/resource.py", line 97, in get
    return self.invoke("GET", relpath, params, headers=headers, allow_redirects=True)
  File "/opt/cloudera/parcels/CDH-5.5.1-1.cdh5.5.1.p0.11/lib/hue/desktop/core/src/desktop/lib/rest/resource.py", line 78, in invoke
    urlencode=self._urlencode)
  File "/opt/cloudera/parcels/CDH-5.5.1-1.cdh5.5.1.p0.11/lib/hue/desktop/core/src/desktop/lib/rest/http_client.py", line 161, in execute
    raise self._exc_class(ex)
WebHdfsException: Unable to authenticate <Response [401]>
[16/Feb/2016 11:04:58 -0800] kerberos_    ERROR    generate_request_header(): authGSSClientStep() failed:
Traceback (most recent call last):
  File "/opt/cloudera/parcels/CDH-5.5.1-1.cdh5.5.1.p0.11/lib/hue/build/env/lib/python2.7/site-packages/requests_kerberos-0.6.1-py2.7.egg/requests_kerberos/kerberos_.py", line 114, in generate_request_header
    _negotiate_value(response))
GSSError: (('Unspecified GSS failure.  Minor code may provide more information', 851968), ('No Kerberos credentials available', -1765328243))
[16/Feb/2016 11:04:58 -0800] kerberos_    ERROR    authenticate_server(): authGSSClientStep() failed:
Traceback (most recent call last):
  File "/opt/cloudera/parcels/CDH-5.5.1-1.cdh5.5.1.p0.11/lib/hue/build/env/lib/python2.7/site-packages/requests_kerberos-0.6.1-py2.7.egg/requests_kerberos/kerberos_.py", line 229, in authenticate_server
    _negotiate_value(response))
GSSError: (('Unspecified GSS failure.  Minor code may provide more information', 851968), ('No Kerberos credentials available', -1765328243))
[16/Feb/2016 11:04:58 -0800] kerberos_    ERROR    handle_mutual_auth(): Mutual authentication failed
[16/Feb/2016 11:04:58 -0800] models       ERROR    Failed to create home directory for user hue: Unable to authenticate <Response [401]>
Traceback (most recent call last):
  File "/opt/cloudera/parcels/CDH-5.5.1-1.cdh5.5.1.p0.11/lib/hue/apps/useradmin/src/useradmin/models.py", line 326, in install_sample_user
    if not fs.do_as_user(SAMPLE_USER_INSTALL, fs.get_home_dir):
  File "/opt/cloudera/parcels/CDH-5.5.1-1.cdh5.5.1.p0.11/lib/hue/desktop/libs/hadoop/src/hadoop/fs/webhdfs.py", line 753, in do_as_user
    return fn(*args, **kwargs)
  File "/opt/cloudera/parcels/CDH-5.5.1-1.cdh5.5.1.p0.11/lib/hue/desktop/libs/hadoop/src/hadoop/fs/webhdfs.py", line 442, in get_home_dir
    res = self._root.get(params=params)
  File "/opt/cloudera/parcels/CDH-5.5.1-1.cdh5.5.1.p0.11/lib/hue/desktop/core/src/desktop/lib/rest/resource.py", line 97, in get
    return self.invoke("GET", relpath, params, headers=headers, allow_redirects=True)
  File "/opt/cloudera/parcels/CDH-5.5.1-1.cdh5.5.1.p0.11/lib/hue/desktop/core/src/desktop/lib/rest/resource.py", line 78, in invoke
    urlencode=self._urlencode)
  File "/opt/cloudera/parcels/CDH-5.5.1-1.cdh5.5.1.p0.11/lib/hue/desktop/core/src/desktop/lib/rest/http_client.py", line 161, in execute
    raise self._exc_class(ex)
WebHdfsException: Unable to authenticate <Response [401]>
[16/Feb/2016 11:04:58 -0800] kerberos_    ERROR    generate_request_header(): authGSSClientStep() failed:
Traceback (most recent call last):
  File "/opt/cloudera/parcels/CDH-5.5.1-1.cdh5.5.1.p0.11/lib/hue/build/env/lib/python2.7/site-packages/requests_kerberos-0.6.1-py2.7.egg/requests_kerberos/kerberos_.py", line 114, in generate_request_header
    _negotiate_value(response))
GSSError: (('Unspecified GSS failure.  Minor code may provide more information', 851968), ('No Kerberos credentials available', -1765328243))
[16/Feb/2016 11:04:58 -0800] kerberos_    ERROR    authenticate_server(): authGSSClientStep() failed:
Traceback (most recent call last):
  File "/opt/cloudera/parcels/CDH-5.5.1-1.cdh5.5.1.p0.11/lib/hue/build/env/lib/python2.7/site-packages/requests_kerberos-0.6.1-py2.7.egg/requests_kerberos/kerberos_.py", line 229, in authenticate_server
    _negotiate_value(response))
GSSError: (('Unspecified GSS failure.  Minor code may provide more information', 851968), ('No Kerberos credentials available', -1765328243))
[16/Feb/2016 11:04:58 -0800] kerberos_    ERROR    handle_mutual_auth(): Mutual authentication failed
[16/Feb/2016 11:04:58 -0800] models       ERROR    Failed to create home directory for user hue: Unable to authenticate <Response [401]>
Traceback (most recent call last):
  File "/opt/cloudera/parcels/CDH-5.5.1-1.cdh5.5.1.p0.11/lib/hue/apps/useradmin/src/useradmin/models.py", line 326, in install_sample_user
    if not fs.do_as_user(SAMPLE_USER_INSTALL, fs.get_home_dir):
  File "/opt/cloudera/parcels/CDH-5.5.1-1.cdh5.5.1.p0.11/lib/hue/desktop/libs/hadoop/src/hadoop/fs/webhdfs.py", line 753, in do_as_user
    return fn(*args, **kwargs)
  File "/opt/cloudera/parcels/CDH-5.5.1-1.cdh5.5.1.p0.11/lib/hue/desktop/libs/hadoop/src/hadoop/fs/webhdfs.py", line 442, in get_home_dir
    res = self._root.get(params=params)
  File "/opt/cloudera/parcels/CDH-5.5.1-1.cdh5.5.1.p0.11/lib/hue/desktop/core/src/desktop/lib/rest/resource.py", line 97, in get
    return self.invoke("GET", relpath, params, headers=headers, allow_redirects=True)
  File "/opt/cloudera/parcels/CDH-5.5.1-1.cdh5.5.1.p0.11/lib/hue/desktop/core/src/desktop/lib/rest/resource.py", line 78, in invoke
    urlencode=self._urlencode)
  File "/opt/cloudera/parcels/CDH-5.5.1-1.cdh5.5.1.p0.11/lib/hue/desktop/core/src/desktop/lib/rest/http_client.py", line 161, in execute
    raise self._exc_class(ex)
WebHdfsException: Unable to authenticate <Response [401]>
[16/Feb/2016 11:04:58 -0800] kerberos_    ERROR    generate_request_header(): authGSSClientStep() failed:
Traceback (most recent call last):
  File "/opt/cloudera/parcels/CDH-5.5.1-1.cdh5.5.1.p0.11/lib/hue/build/env/lib/python2.7/site-packages/requests_kerberos-0.6.1-py2.7.egg/requests_kerberos/kerberos_.py", line 114, in generate_request_header
    _negotiate_value(response))
GSSError: (('Unspecified GSS failure.  Minor code may provide more information', 851968), ('No Kerberos credentials available', -1765328243))
[16/Feb/2016 11:04:58 -0800] kerberos_    ERROR    authenticate_server(): authGSSClientStep() failed:
Traceback (most recent call last):
  File "/opt/cloudera/parcels/CDH-5.5.1-1.cdh5.5.1.p0.11/lib/hue/build/env/lib/python2.7/site-packages/requests_kerberos-0.6.1-py2.7.egg/requests_kerberos/kerberos_.py", line 229, in authenticate_server
    _negotiate_value(response))
GSSError: (('Unspecified GSS failure.  Minor code may provide more information', 851968), ('No Kerberos credentials available', -1765328243))
[16/Feb/2016 11:04:58 -0800] kerberos_    ERROR    handle_mutual_auth(): Mutual authentication failed
[16/Feb/2016 11:04:58 -0800] models       ERROR    Failed to create home directory for user hue: Unable to authenticate <Response [401]>
Traceback (most recent call last):
  File "/opt/cloudera/parcels/CDH-5.5.1-1.cdh5.5.1.p0.11/lib/hue/apps/useradmin/src/useradmin/models.py", line 326, in install_sample_user
    if not fs.do_as_user(SAMPLE_USER_INSTALL, fs.get_home_dir):
  File "/opt/cloudera/parcels/CDH-5.5.1-1.cdh5.5.1.p0.11/lib/hue/desktop/libs/hadoop/src/hadoop/fs/webhdfs.py", line 753, in do_as_user
    return fn(*args, **kwargs)
  File "/opt/cloudera/parcels/CDH-5.5.1-1.cdh5.5.1.p0.11/lib/hue/desktop/libs/hadoop/src/hadoop/fs/webhdfs.py", line 442, in get_home_dir
    res = self._root.get(params=params)
  File "/opt/cloudera/parcels/CDH-5.5.1-1.cdh5.5.1.p0.11/lib/hue/desktop/core/src/desktop/lib/rest/resource.py", line 97, in get
    return self.invoke("GET", relpath, params, headers=headers, allow_redirects=True)
  File "/opt/cloudera/parcels/CDH-5.5.1-1.cdh5.5.1.p0.11/lib/hue/desktop/core/src/desktop/lib/rest/resource.py", line 78, in invoke
    urlencode=self._urlencode)
  File "/opt/cloudera/parcels/CDH-5.5.1-1.cdh5.5.1.p0.11/lib/hue/desktop/core/src/desktop/lib/rest/http_client.py", line 161, in execute
    raise self._exc_class(ex)
WebHdfsException: Unable to authenticate <Response [401]>
[16/Feb/2016 11:04:58 -0800] kerberos_    ERROR    generate_request_header(): authGSSClientStep() failed:
Traceback (most recent call last):
  File "/opt/cloudera/parcels/CDH-5.5.1-1.cdh5.5.1.p0.11/lib/hue/build/env/lib/python2.7/site-packages/requests_kerberos-0.6.1-py2.7.egg/requests_kerberos/kerberos_.py", line 114, in generate_request_header
    _negotiate_value(response))
GSSError: (('Unspecified GSS failure.  Minor code may provide more information', 851968), ('No Kerberos credentials available', -1765328243))
[16/Feb/2016 11:04:58 -0800] kerberos_    ERROR    authenticate_server(): authGSSClientStep() failed:
Traceback (most recent call last):
  File "/opt/cloudera/parcels/CDH-5.5.1-1.cdh5.5.1.p0.11/lib/hue/build/env/lib/python2.7/site-packages/requests_kerberos-0.6.1-py2.7.egg/requests_kerberos/kerberos_.py", line 229, in authenticate_server
    _negotiate_value(response))
GSSError: (('Unspecified GSS failure.  Minor code may provide more information', 851968), ('No Kerberos credentials available', -1765328243))
[16/Feb/2016 11:04:58 -0800] kerberos_    ERROR    handle_mutual_auth(): Mutual authentication failed
[16/Feb/2016 11:04:58 -0800] models       ERROR    Failed to create home directory for user hue: Unable to authenticate <Response [401]>
Traceback (most recent call last):
  File "/opt/cloudera/parcels/CDH-5.5.1-1.cdh5.5.1.p0.11/lib/hue/apps/useradmin/src/useradmin/models.py", line 326, in install_sample_user
    if not fs.do_as_user(SAMPLE_USER_INSTALL, fs.get_home_dir):
  File "/opt/cloudera/parcels/CDH-5.5.1-1.cdh5.5.1.p0.11/lib/hue/desktop/libs/hadoop/src/hadoop/fs/webhdfs.py", line 753, in do_as_user
    return fn(*args, **kwargs)
  File "/opt/cloudera/parcels/CDH-5.5.1-1.cdh5.5.1.p0.11/lib/hue/desktop/libs/hadoop/src/hadoop/fs/webhdfs.py", line 442, in get_home_dir
    res = self._root.get(params=params)
  File "/opt/cloudera/parcels/CDH-5.5.1-1.cdh5.5.1.p0.11/lib/hue/desktop/core/src/desktop/lib/rest/resource.py", line 97, in get
    return self.invoke("GET", relpath, params, headers=headers, allow_redirects=True)
  File "/opt/cloudera/parcels/CDH-5.5.1-1.cdh5.5.1.p0.11/lib/hue/desktop/core/src/desktop/lib/rest/resource.py", line 78, in invoke
    urlencode=self._urlencode)
  File "/opt/cloudera/parcels/CDH-5.5.1-1.cdh5.5.1.p0.11/lib/hue/desktop/core/src/desktop/lib/rest/http_client.py", line 161, in execute
    raise self._exc_class(ex)
WebHdfsException: Unable to authenticate <Response [401]>
[16/Feb/2016 11:04:58 -0800] kerberos_    ERROR    generate_request_header(): authGSSClientStep() failed:
Traceback (most recent call last):
  File "/opt/cloudera/parcels/CDH-5.5.1-1.cdh5.5.1.p0.11/lib/hue/build/env/lib/python2.7/site-packages/requests_kerberos-0.6.1-py2.7.egg/requests_kerberos/kerberos_.py", line 114, in generate_request_header
    _negotiate_value(response))
GSSError: (('Unspecified GSS failure.  Minor code may provide more information', 851968), ('No Kerberos credentials available', -1765328243))
[16/Feb/2016 11:04:58 -0800] kerberos_    ERROR    authenticate_server(): authGSSClientStep() failed:
Traceback (most recent call last):
  File "/opt/cloudera/parcels/CDH-5.5.1-1.cdh5.5.1.p0.11/lib/hue/build/env/lib/python2.7/site-packages/requests_kerberos-0.6.1-py2.7.egg/requests_kerberos/kerberos_.py", line 229, in authenticate_server
    _negotiate_value(response))
GSSError: (('Unspecified GSS failure.  Minor code may provide more information', 851968), ('No Kerberos credentials available', -1765328243))
[16/Feb/2016 11:04:58 -0800] kerberos_    ERROR    handle_mutual_auth(): Mutual authentication failed
[16/Feb/2016 11:04:58 -0800] models       ERROR    Failed to create home directory for user hue: Unable to authenticate <Response [401]>
Traceback (most recent call last):
  File "/opt/cloudera/parcels/CDH-5.5.1-1.cdh5.5.1.p0.11/lib/hue/apps/useradmin/src/useradmin/models.py", line 326, in install_sample_user
    if not fs.do_as_user(SAMPLE_USER_INSTALL, fs.get_home_dir):
  File "/opt/cloudera/parcels/CDH-5.5.1-1.cdh5.5.1.p0.11/lib/hue/desktop/libs/hadoop/src/hadoop/fs/webhdfs.py", line 753, in do_as_user
    return fn(*args, **kwargs)
  File "/opt/cloudera/parcels/CDH-5.5.1-1.cdh5.5.1.p0.11/lib/hue/desktop/libs/hadoop/src/hadoop/fs/webhdfs.py", line 442, in get_home_dir
    res = self._root.get(params=params)
  File "/opt/cloudera/parcels/CDH-5.5.1-1.cdh5.5.1.p0.11/lib/hue/desktop/core/src/desktop/lib/rest/resource.py", line 97, in get
    return self.invoke("GET", relpath, params, headers=headers, allow_redirects=True)
  File "/opt/cloudera/parcels/CDH-5.5.1-1.cdh5.5.1.p0.11/lib/hue/desktop/core/src/desktop/lib/rest/resource.py", line 78, in invoke
    urlencode=self._urlencode)
  File "/opt/cloudera/parcels/CDH-5.5.1-1.cdh5.5.1.p0.11/lib/hue/desktop/core/src/desktop/lib/rest/http_client.py", line 161, in execute
    raise self._exc_class(ex)
WebHdfsException: Unable to authenticate <Response [401]>
[16/Feb/2016 11:04:58 -0800] kerberos_    ERROR    generate_request_header(): authGSSClientStep() failed:
Traceback (most recent call last):
  File "/opt/cloudera/parcels/CDH-5.5.1-1.cdh5.5.1.p0.11/lib/hue/build/env/lib/python2.7/site-packages/requests_kerberos-0.6.1-py2.7.egg/requests_kerberos/kerberos_.py", line 114, in generate_request_header
    _negotiate_value(response))
GSSError: (('Unspecified GSS failure.  Minor code may provide more information', 851968), ('No Kerberos credentials available', -1765328243))
[16/Feb/2016 11:04:58 -0800] kerberos_    ERROR    authenticate_server(): authGSSClientStep() failed:
Traceback (most recent call last):
  File "/opt/cloudera/parcels/CDH-5.5.1-1.cdh5.5.1.p0.11/lib/hue/build/env/lib/python2.7/site-packages/requests_kerberos-0.6.1-py2.7.egg/requests_kerberos/kerberos_.py", line 229, in authenticate_server
    _negotiate_value(response))
GSSError: (('Unspecified GSS failure.  Minor code may provide more information', 851968), ('No Kerberos credentials available', -1765328243))
[16/Feb/2016 11:04:58 -0800] kerberos_    ERROR    handle_mutual_auth(): Mutual authentication failed
[16/Feb/2016 11:04:58 -0800] models       ERROR    Failed to create home directory for user hue: Unable to authenticate <Response [401]>
Traceback (most recent call last):
  File "/opt/cloudera/parcels/CDH-5.5.1-1.cdh5.5.1.p0.11/lib/hue/apps/useradmin/src/useradmin/models.py", line 326, in install_sample_user
    if not fs.do_as_user(SAMPLE_USER_INSTALL, fs.get_home_dir):
  File "/opt/cloudera/parcels/CDH-5.5.1-1.cdh5.5.1.p0.11/lib/hue/desktop/libs/hadoop/src/hadoop/fs/webhdfs.py", line 753, in do_as_user
    return fn(*args, **kwargs)
  File "/opt/cloudera/parcels/CDH-5.5.1-1.cdh5.5.1.p0.11/lib/hue/desktop/libs/hadoop/src/hadoop/fs/webhdfs.py", line 442, in get_home_dir
    res = self._root.get(params=params)
  File "/opt/cloudera/parcels/CDH-5.5.1-1.cdh5.5.1.p0.11/lib/hue/desktop/core/src/desktop/lib/rest/resource.py", line 97, in get
    return self.invoke("GET", relpath, params, headers=headers, allow_redirects=True)
  File "/opt/cloudera/parcels/CDH-5.5.1-1.cdh5.5.1.p0.11/lib/hue/desktop/core/src/desktop/lib/rest/resource.py", line 78, in invoke
    urlencode=self._urlencode)
  File "/opt/cloudera/parcels/CDH-5.5.1-1.cdh5.5.1.p0.11/lib/hue/desktop/core/src/desktop/lib/rest/http_client.py", line 161, in execute
    raise self._exc_class(ex)
WebHdfsException: Unable to authenticate <Response [401]>
